Workbook

Sheet MarketData
A1: MARKET DATA — USD SOFR curve (THE ONLY HARD-CODED SHEET)
A2: All other sheets are formula-driven and reference this sheet.
A4: Valuation date | B4: 46177
A5: Spot date (T+2) | B5: 46181
A6: Day count / Lookback | B6: ACT/360 | 5 business-day lag (compounded SOFR)
A8: 1) OVERNIGHT (SOFR O/N — discounts valuation date to first FOMC step)
A10: Tenor | B10: Start | C10: End | D10: Rate
A11: 1D | B11: 46177 | C11: 46191 | D11: 0.035947
A13: 2) FOMC-DATED STEP QUOTES (near-term SOFR path)
A14: Start | B14: End | C14: Rate
A16: 46191 | B16: 46203 | C16: 0.036301
A17: 46203 | B17: 46282 | C17: 0.036711
A18: 46282 | B18: 46324 | C18: 0.037243
A19: 46324 | B19: 46366 | C19: 0.037679
A20: 46366 | B20: 46415 | C20: 0.038647
A21: 46415 | B21: 46464 | C21: 0.038641
A22: 46464 | B22: 46506 | C22: 0.039284
A23: 46506 | B23: 46548 | C23: 0.039925
A25: 3) EUSD QUARTERLY SOFR FUTURES (price + convexity; covers 2027-06 → 2029-06)
A26: Contract | B26: IMM Start | C26: IMM End | D26: Price | E26: Convexity (%)
A27: JUN27 | B27: 46554 | C27: 46645 | D27: 95.9993 | E27: 0.0035
A28: SEP27 | B28: 46645 | C28: 46736 | D28: 96.0035 | E28: 0.0054
A29: DEC27 | B29: 46736 | C29: 46827 | D29: 96.0252 | E29: 0.0079
A30: MAR28 | B30: 46827 | C30: 46925 | D30: 96.0792 | E30: 0.0112
A31: JUN28 | B31: 46925 | C31: 47016 | D31: 96.1217 | E31: 0.0154
A32: SEP28 | B32: 47016 | C32: 47107 | D32: 96.1496 | E32: 0.0201
A33: DEC28 | B33: 47107 | C33: 47198 | D33: 96.1468 | E33: 0.0257
A34: MAR29 | B34: 47198 | C34: 47289 | D34: 96.1431 | E34: 0.0308
A36: 4) PAR SOFR SWAPS (annual, ACT/360)
A37: Tenor (Y) | B37: Maturity | C37: Par Rate
A38: 4 | B38: 47642 | C38: 0.03911
A39: 5 | B39: 48007 | C39: 0.039216
A40: 6 | B40: 48373 | C40: 0.039468
A41: 7 | B41: 48738 | C41: 0.039771
A42: 8 | B42: 49103 | C42: 0.040086
A43: 9 | B43: 49468 | C43: 0.040411
A44: 10 | B44: 49834 | C44: 0.040746
A45: 11 | B45: 50199 | C45: 0.041087
A46: 12 | B46: 50564 | C46: 0.041423
A49: 5) PANDORA CURVE (reference output — for comparison only)
...

Sheet Bootstrap
A1: BOOTSTRAP — SOFR curve built from MarketData (all formulas)
A3: FRONT — O/N + FOMC steps (exact: DF = previous DF / (1 + rate × τ), ACT/360)
A4: Node date | B4: Prev date | C4: Days | D4: τ (ACT/360) | E4: Rate | F4: DF
A5: =MarketData!$B$4 -> 46177 | F5: 1
A6: =MarketData!$C$11 -> 46191 | B6: =A5 -> 46177 | C6: =A6-B6 -> 14 | D6: =C6/360 -> 0.038888889 | E6: =MarketData!$D$11 -> 0.035947 | F6: =F5/(1+E6*D6) -> 0.99860401
A7: =MarketData!$B$16 -> 46203 | B7: =A6 -> 46191 | C7: =A7-B7 -> 12 | D7: =C7/360 -> 0.033333333 | E7: =MarketData!$C$16 -> 0.036301 | F7: =F6/(1+E7*D7) -> 0.99739713
A8: =MarketData!$B$17 -> 46282 | B8: =A7 -> 46203 | C8: =A8-B8 -> 79 | D8: =C8/360 -> 0.21944444 | E8: =MarketData!$C$17 -> 0.036711 | F8: =F7/(1+E8*D8) -> 0.98942629
A9: =MarketData!$B$18 -> 46324 | B9: =A8 -> 46282 | C9: =A9-B9 -> 42 | D9: =C9/360 -> 0.11666667 | E9: =MarketData!$C$18 -> 0.037243 | F9: =F8/(1+E9*D9) -> 0.98514581
A10: =MarketData!$B$19 -> 46366 | B10: =A9 -> 46324 | C10: =A10-B10 -> 42 | D10: =C10/360 -> 0.11666667 | E10: =MarketData!$C$19 -> 0.037679 | F10: =F9/(1+E10*D10) -> 0.98083418
A11: =MarketData!$B$20 -> 46415 | B11: =A10 -> 46366 | C11: =A11-B11 -> 49 | D11: =C11/360 -> 0.13611111 | E11: =MarketData!$C$20 -> 0.038647 | F11: =F10/(1+E11*D11) -> 0.97570171
A12: =MarketData!$B$21 -> 46464 | B12: =A11 -> 46415 | C12: =A12-B12 -> 49 | D12: =C12/360 -> 0.13611111 | E12: =MarketData!$C$21 -> 0.038641 | F12: =F11/(1+E12*D12) -> 0.97059688
A13: =MarketData!$B$22 -> 46506 | B13: =A12 -> 46464 | C13: =A13-B13 -> 42 | D13: =C13/360 -> 0.11666667 | E13: =MarketData!$C$22 -> 0.039284 | F13: =F12/(1+E13*D13) -> 0.9661688
A14: =MarketData!$B$23 -> 46548 | B14: =A13 -> 46506 | C14: =A14-B14 -> 42 | D14: =C14/360 -> 0.11666667 | E14: =MarketData!$C$23 -> 0.039925 | F14: =F13/(1+E14*D14) -> 0.96168933
A15: =MarketData!$B$27 -> 46554 | B15: =A14 -> 46548 | C15: =A15-B15 -> 6 | D15: =C15/360 -> 0.016666667 | E15: =MarketData!$C$23 -> 0.039925 | F15: =F14/(1+E15*D15) -> 0.96104984 | G15: ← anchor (last step rate extended to first IMM date)
A17: FUTURES — EUSD chain (Fwd = (100 − Price − Convexity)/100; DF telescopes from the front)
A18: Contract | B18: IMM Start | C18: IMM End | D18: Price | E18: Conv (%) | F18: Fwd | G18: Days | H18: τ | I18: DF(start) | J18: DF(end)
A19: =MarketData!$A$27 -> JUN27 | B19: =MarketData!$B$27 -> 46554 | C19: =MarketData!$C$27 -> 46645 | D19: =MarketData!$D$27 -> 95.9993 | E19: =MarketData!$E$27 -> 0.0035 | F19: =(100-D19-E19)/100 -> 0.039972 | G19: =C19-B19 -> 91 | H19: =G19/360 -> 0.25277778 | I19: =$F$15 -> 0.96104984 | J19: =I19/(1+F19*H19) -> 0.95143649
A20: =MarketData!$A$28 -> SEP27 | B20: =MarketData!$B$28 -> 46645 | C20: =MarketData!$C$28 -> 46736 | D20: =MarketData!$D$28 -> 96.0035 | E20: =MarketData!$E$28 -> 0.0054 | F20: =(100-D20-E20)/100 -> 0.039911 | G20: =C20-B20 -> 91 | H20: =G20/360 -> 0.25277778 | I20: =J19 -> 0.95143649 | J20: =I20/(1+F20*H20) -> 0.94193368
A21: =MarketData!$A$29 -> DEC27 | B21: =MarketData!$B$29 -> 46736 | C21: =MarketData!$C$29 -> 46827 | D21: =MarketData!$D$29 -> 96.0252 | E21: =MarketData!$E$29 -> 0.0079 | F21: =(100-D21-E21)/100 -> 0.039669 | G21: =C21-B21 -> 91 | H21: =G21/360 -> 0.25277778 | I21: =J20 -> 0.94193368 | J21: =I21/(1+F21*H21) -> 0.93258227
A22: =MarketData!$A$30 -> MAR28 | B22: =MarketData!$B$30 -> 46827 | C22: =MarketData!$C$30 -> 46925 | D22: =MarketData!$D$30 -> 96.0792 | E22: =MarketData!$E$30 -> 0.0112 | F22: =(100-D22-E22)/100 -> 0.039096 | G22: =C22-B22 -> 98 | H22: =G22/360 -> 0.27222222 | I22: =J21 -> 0.93258227 | J22: =I22/(1+F22*H22) -> 0.9227615
A23: =MarketData!$A$31 -> JUN28 | B23: =MarketData!$B$31 -> 46925 | C23: =MarketData!$C$31 -> 47016 | D23: =MarketData!$D$31 -> 96.1217 | E23: =MarketData!$E$31 -> 0.0154 | F23: =(100-D23-E23)/100 -> 0.038629 | G23: =C23-B23 -> 91 | H23: =G23/360 -> 0.25277778 | I23: =J22 -> 0.9227615 | J23: =I23/(1+F23*H23) -> 0.91383828
A24: =MarketData!$A$32 -> SEP28 | B24: =MarketData!$B$32 -> 47016 | C24: =MarketData!$C$32 -> 47107 | D24: =MarketData!$D$32 -> 96.1496 | E24: =MarketData!$E$32 -> 0.0201 | F24: =(100-D24-E24)/100 -> 0.038303 | G24: =C24-B24 -> 91 | H24: =G24/360 -> 0.25277778 | I24: =J23 -> 0.91383828 | J24: =I24/(1+F24*H24) -> 0.90507521
A25: =MarketData!$A$33 -> DEC28 | B25: =MarketData!$B$33 -> 47107 | C25: =MarketData!$C$33 -> 47198 | D25: =MarketData!$D$33 -> 96.1468 | E25: =MarketData!$E$33 -> 0.0257 | F25: =(100-D25-E25)/100 -> 0.038275 | G25: =C25-B25 -> 91 | H25: =G25/360 -> 0.25277778 | I25: =J24 -> 0.90507521 | J25: =I25/(1+F25*H25) -> 0.89640245
A26: =MarketData!$A$34 -> MAR29 | B26: =MarketData!$B$34 -> 47198 | C26: =MarketData!$C$34 -> 47289 | D26: =MarketData!$D$34 -> 96.1431 | E26: =MarketData!$E$34 -> 0.0308 | F26: =(100-D26-E26)/100 -> 0.038261 | G26: =C26-B26 -> 91 | H26: =G26/360 -> 0.25277778 | I26: =J25 -> 0.89640245 | J26: =I26/(1+F26*H26) -> 0.88781592
A28: SWAP SOLVES — close out the long end (annual fixed leg from spot, ACT/360; 5Y added as sentinel node)
A29: Spot date | B29: =MarketData!$B$5 -> 46181 | D29: Spot DF | E29: =1/(1+MarketData!$D$11*(B29-MarketData!$B$4)/360) -> 0.99960075
A30: Fixed date | B30: DF | C30: τ (ACT/360)
A31: =EDATE(B29,12) -> 46546 | B31: =F13*(F14/F13)^((A31-A13)/(A14-A13)) -> 0.96190217 | C31: =(A31-B29)/360 -> 1.0138889
A32: =EDATE(B29,24) -> 46912 | B32: =J21*(J22/J21)^((A32-C21)/(C22-C21)) -> 0.92405829 | C32: =(A32-A31)/360 -> 1.0166667
A33: =EDATE(B29,36) -> 47277 | B33: =J25*(J26/J25)^((A33-C25)/(C26-C25)) -> 0.88894348 | C33: =(A33-A32)/360 -> 1.0138889
A34: =MarketData!$B$38 -> 47642 | B34: =(E29-MarketData!$C$38*(C31*B31+C32*B32+C33*B33))/(1+MarketData!$C$38*C34) -> 0.8555416 | C34: =(A34-A33)/360 -> 1.0138889 | E34: ← 4Y par solve (DF at 2030 maturity)
A35: =MarketData!$B$39 -> 48007 | B35: =(E29-MarketData!$C$39*(C31*B31+C32*B32+C33*B33+C34*B34))/(1+MarketData!$C$39*C35) -> 0.82244999 | C35: =(A35-A34)/360 -> 1.0138889 | E35: ← 5Y par solve (sentinel)
A37: CURVE NODES (sorted) — the interpolation grid (log-linear on ln DF) used by the Curve and Interpolation sheets
A38: Node date | B38: Time (yrs, ACT/360) | C38: DF | D38: ln(DF)
A39: =A5 -> 46177 | B39: =(A39-MarketData!$B$4)/360 -> 0 | C39: =F5 -> 1 | D39: =LN(C39) -> 0
A40: =A6 -> 46191 | B40: =(A40-MarketData!$B$4)/360 -> 0.038888889 | C40: =F6 -> 0.99860401 | D40: =LN(C40) -> -0.0013969627
A41: =A7 -> 46203 | B41: =(A41-MarketData!$B$4)/360 -> 0.072222222 | C41: =F7 -> 0.99739713 | D41: =LN(C41) -> -0.0026062645
A42: =A8 -> 46282 | B42: =(A42-MarketData!$B$4)/360 -> 0.29166667 | C42: =F8 -> 0.98942629 | D42: =LN(C42) -> -0.010630013
A43: =A9 -> 46324 | B43: =(A43-MarketData!$B$4)/360 -> 0.40833333 | C43: =F9 -> 0.98514581 | D43: =LN(C43) -> -0.014965617
A44: =A10 -> 46366 | B44: =(A44-MarketData!$B$4)/360 -> 0.525 | C44: =F10 -> 0.98083418 | D44: =LN(C44) -> -0.019351867
...

Sheet Curve
A1: CURVE — discount factor & forward rate for every date, vs Pandora
A2: DF: log-linear on ln DF over the Bootstrap node grid. Forward: compounded SOFR with 5-business-day lag (WORKDAY −5).
A4: Date | B4: Time | C4: My DF | D4: Pandora DF | E4: Δ zero (bp) mine−Pandora | F4: Next date | G4: τ | H4: Lag start | I4: Lag end | J4: DF(lag start) | K4: DF(lag end) | L4: My Forward | M4: Pandora Fwd | N4: Δ fwd (bp) mine−Pandora
A5: =MarketData!$A$51 -> 46195 | B5: =(A5-MarketData!$B$4)/360 -> 0.05 | C5: =EXP(INDEX(Bootstrap!$D$39:$D$59,MATCH($B5,Bootstrap!$B$39:$B$59,1))+(INDEX(Bootstrap!$D$39:$D$59,MATCH($B5,Bootstrap!$B$39:$B$59,1)+1)-INDEX(Bootstrap!$D$39:$D$59,MATCH($B5,Bootstrap!$B$39:$B$59,1)))*(($B5)-INDEX(Bootstrap!$B$39:$B$59,MATCH($B5,Bootstrap!$B$39:$B$59,1)))/(INDEX(Bootstrap!$B$39:$B$59,MATCH($B5,Bootstrap!$B$39:$B$59,1)+1)-INDEX(Bootstrap!$B$39:$B$59,MATCH($B5,Bootstrap!$B$39:$B$59,1)))) -> 0.99820156 | D5: =MarketData!$B$51 -> 0.99820126 | E5: =(LN(D5)-LN(C5))/B5*10000 -> -0.059677186 | F5: =A6 -> 46223 | G5: =(F5-A5)/360 -> 0.077777778 | H5: =WORKDAY(A5,-5) -> 46188 | I5: =WORKDAY(F5,-5) -> 46216 | J5: =EXP(INDEX(Bootstrap!$D$39:$D$59,MATCH((($H5-MarketData!$B$4)/360),Bootstrap!$B$39:$B$59,1))+(INDEX(Bootstrap!$D$39:$D$59,MATCH((($H5-MarketData!$B$4)/360),Bootstrap!$B$39:$B$59,1)+1)-INDEX(Bootstrap!$D$39:$D$59,MATCH((($H5-MarketData!$B$4)/360),Bootstrap!$B$39:$B$59,1)))*(((($H5-MarketData!$B$4)/360))-INDEX(Bootstrap!$B$39:$B$59,MATCH((($H5-MarketData!$B$4)/360),Bootstrap!$B$39:$B$59,1)))/(INDEX(Bootstrap!$B$39:$B$59,MATCH((($H5-MarketData!$B$4)/360),Bootstrap!$B$39:$B$59,1)+1)-INDEX(Bootstrap!$B$39:$B$59,MATCH((($H5-MarketData!$B$4)/360),Bootstrap!$B$39:$B$59,1)))) -> 0.99890299 | K5: =EXP(INDEX(Bootstrap!$D$39:$D$59,MATCH((($I5-MarketData!$B$4)/360),Bootstrap!$B$39:$B$59,1))+(INDEX(Bootstrap!$D$39:$D$59,MATCH((($I5-MarketData!$B$4)/360),Bootstrap!$B$39:$B$59,1)+1)-INDEX(Bootstrap!$D$39:$D$59,MATCH((($I5-MarketData!$B$4)/360),Bootstrap!$B$39:$B$59,1)))*(((($I5-MarketData!$B$4)/360))-INDEX(Bootstrap!$B$39:$B$59,MATCH((($I5-MarketData!$B$4)/360),Bootstrap!$B$39:$B$59,1)))/(INDEX(Bootstrap!$B$39:$B$59,MATCH((($I5-MarketData!$B$4)/360),Bootstrap!$B$39:$B$59,1)+1)-INDEX(Bootstrap!$B$39:$B$59,MATCH((($I5-MarketData!$B$4)/360),Bootstrap!$B$39:$B$59,1)))) -> 0.99608107 | L5: =(J5/K5-1)/G5 -> 0.036424544 | M5: =MarketData!$C$51 -> 0.036236303 | N5: =(L5-M5)*10000 -> 1.8824119
A6: =MarketData!$A$52 -> 46223 | B6: =(A6-MarketData!$B$4)/360 -> 0.12777778 | C6: =EXP(INDEX(Bootstrap!$D$39:$D$59,MATCH($B6,Bootstrap!$B$39:$B$59,1))+(INDEX(Bootstrap!$D$39:$D$59,MATCH($B6,Bootstrap!$B$39:$B$59,1)+1)-INDEX(Bootstrap!$D$39:$D$59,MATCH($B6,Bootstrap!$B$39:$B$59,1)))*(($B6)-INDEX(Bootstrap!$B$39:$B$59,MATCH($B6,Bootstrap!$B$39:$B$59,1)))/(INDEX(Bootstrap!$B$39:$B$59,MATCH($B6,Bootstrap!$B$39:$B$59,1)+1)-INDEX(Bootstrap!$B$39:$B$59,MATCH($B6,Bootstrap!$B$39:$B$59,1)))) -> 0.99537314 | D6: =MarketData!$B$52 -> 0.99539283 | E6: =(LN(D6)-LN(C6))/B6*10000 -> 1.5481991 | F6: =A7 -> 46254 | G6: =(F6-A6)/360 -> 0.086111111 | H6: =WORKDAY(A6,-5) -> 46216 | I6: =WORKDAY(F6,-5) -> 46247 | J6: =EXP(INDEX(Bootstrap!$D$39:$D$59,MATCH((($H6-MarketData!$B$4)/360),Bootstrap!$B$39:$B$59,1))+(INDEX(Bootstrap!$D$39:$D$59,MATCH((($H6-MarketData!$B$4)/360),Bootstrap!$B$39:$B$59,1)+1)-INDEX(Bootstrap!$D$39:$D$59,MATCH((($H6-MarketData!$B$4)/360),Bootstrap!$B$39:$B$59,1)))*(((($H6-MarketData!$B$4)/360))-INDEX(Bootstrap!$B$39:$B$59,MATCH((($H6-MarketData!$B$4)/360),Bootstrap!$B$39:$B$59,1)))/(INDEX(Bootstrap!$B$39:$B$59,MATCH((($H6-MarketData!$B$4)/360),Bootstrap!$B$39:$B$59,1)+1)-INDEX(Bootstrap!$B$39:$B$59,MATCH((($H6-MarketData!$B$4)/360),Bootstrap!$B$39:$B$59,1)))) -> 0.99608107 | K6: =EXP(INDEX(Bootstrap!$D$39:$D$59,MATCH((($I6-MarketData!$B$4)/360),Bootstrap!$B$39:$B$59,1))+(INDEX(Bootstrap!$D$39:$D$59,MATCH((($I6-MarketData!$B$4)/360),Bootstrap!$B$39:$B$59,1)+1)-INDEX(Bootstrap!$D$39:$D$59,MATCH((($I6-MarketData!$B$4)/360),Bootstrap!$B$39:$B$59,1)))*(((($I6-MarketData!$B$4)/360))-INDEX(Bootstrap!$B$39:$B$59,MATCH((($I6-MarketData!$B$4)/360),Bootstrap!$B$39:$B$59,1)))/(INDEX(Bootstrap!$B$39:$B$59,MATCH((($I6-MarketData!$B$4)/360),Bootstrap!$B$39:$B$59,1)+1)-INDEX(Bootstrap!$B$39:$B$59,MATCH((($I6-MarketData!$B$4)/360),Bootstrap!$B$39:$B$59,1)))) -> 0.99294978 | L6: =(J6/K6-1)/G6 -> 0.036621539 | M6: =MarketData!$C$52 -> 0.036459958 | N6: =(L6-M6)*10000 -> 1.6158184
A7: =MarketData!$A$53 -> 46254 | B7: =(A7-MarketData!$B$4)/360 -> 0.21388889 | C7: =EXP(INDEX(Bootstrap!$D$39:$D$59,MATCH($B7,Bootstrap!$B$39:$B$59,1))+(INDEX(Bootstrap!$D$39:$D$59,MATCH($B7,Bootstrap!$B$39:$B$59,1)+1)-INDEX(Bootstrap!$D$39:$D$59,MATCH($B7,Bootstrap!$B$39:$B$59,1)))*(($B7)-INDEX(Bootstrap!$B$39:$B$59,MATCH($B7,Bootstrap!$B$39:$B$59,1)))/(INDEX(Bootstrap!$B$39:$B$59,MATCH($B7,Bootstrap!$B$39:$B$59,1)+1)-INDEX(Bootstrap!$B$39:$B$59,MATCH($B7,Bootstrap!$B$39:$B$59,1)))) -> 0.99224408 | D7: =MarketData!$B$53 -> 0.99226985 | E7: =(LN(D7)-LN(C7))/B7*10000 -> 1.2140537 | F7: =A8 -> 46286 | G7: =(F7-A7)/360 -> 0.088888889 | H7: =WORKDAY(A7,-5) -> 46247 | I7: =WORKDAY(F7,-5) -> 46279 | J7: =EXP(INDEX(Bootstrap!$D$39:$D$59,MATCH((($H7-MarketData!$B$4)/360),Bootstrap!$B$39:$B$59,1))+(INDEX(Bootstrap!$D$39:$D$59,MATCH((($H7-MarketData!$B$4)/360),Bootstrap!$B$39:$B$59,1)+1)-INDEX(Bootstrap!$D$39:$D$59,MATCH((($H7-MarketData!$B$4)/360),Bootstrap!$B$39:$B$59,1)))*(((($H7-MarketData!$B$4)/360))-INDEX(Bootstrap!$B$39:$B$59,MATCH((($H7-MarketData!$B$4)/360),Bootstrap!$B$39:$B$59,1)))/(INDEX(Bootstrap!$B$39:$B$59,MATCH((($H7-MarketData!$B$4)/360),Bootstrap!$B$39:$B$59,1)+1)-INDEX(Bootstrap!$B$39:$B$59,MATCH((($H7-MarketData!$B$4)/360),Bootstrap!$B$39:$B$59,1)))) -> 0.99294978 | K7: =EXP(INDEX(Bootstrap!$D$39:$D$59,MATCH((($I7-MarketData!$B$4)/360),Bootstrap!$B$39:$B$59,1))+(INDEX(Bootstrap!$D$39:$D$59,MATCH((($I7-MarketData!$B$4)/360),Bootstrap!$B$39:$B$59,1)+1)-INDEX(Bootstrap!$D$39:$D$59,MATCH((($I7-MarketData!$B$4)/360),Bootstrap!$B$39:$B$59,1)))*(((($I7-MarketData!$B$4)/360))-INDEX(Bootstrap!$B$39:$B$59,MATCH((($I7-MarketData!$B$4)/360),Bootstrap!$B$39:$B$59,1)))/(INDEX(Bootstrap!$B$39:$B$59,MATCH((($I7-MarketData!$B$4)/360),Bootstrap!$B$39:$B$59,1)+1)-INDEX(Bootstrap!$B$39:$B$59,MATCH((($I7-MarketData!$B$4)/360),Bootstrap!$B$39:$B$59,1)))) -> 0.98972781 | L7: =(J7/K7-1)/G7 -> 0.0366234 | M7: =MarketData!$C$53 -> 0.036678842 | N7: =(L7-M7)*10000 -> -0.55441766
A8: =MarketData!$A$54 -> 46286 | B8: =(A8-MarketData!$B$4)/360 -> 0.30277778 | C8: =EXP(INDEX(Bootstrap!$D$39:$D$59,MATCH($B8,Bootstrap!$B$39:$B$59,1))+(INDEX(Bootstrap!$D$39:$D$59,MATCH($B8,Bootstrap!$B$39:$B$59,1)+1)-INDEX(Bootstrap!$D$39:$D$59,MATCH($B8,Bootstrap!$B$39:$B$59,1)))*(($B8)-INDEX(Bootstrap!$B$39:$B$59,MATCH($B8,Bootstrap!$B$39:$B$59,1)))/(INDEX(Bootstrap!$B$39:$B$59,MATCH($B8,Bootstrap!$B$39:$B$59,1)+1)-INDEX(Bootstrap!$B$39:$B$59,MATCH($B8,Bootstrap!$B$39:$B$59,1)))) -> 0.98901782 | D8: =MarketData!$B$54 -> 0.98903922 | E8: =(LN(D8)-LN(C8))/B8*10000 -> 0.71464196 | F8: =A9 -> 46315 | G8: =(F8-A8)/360 -> 0.080555556 | H8: =WORKDAY(A8,-5) -> 46279 | I8: =WORKDAY(F8,-5) -> 46308 | J8: =EXP(INDEX(Bootstrap!$D$39:$D$59,MATCH((($H8-MarketData!$B$4)/360),Bootstrap!$B$39:$B$59,1))+(INDEX(Bootstrap!$D$39:$D$59,MATCH((($H8-MarketData!$B$4)/360),Bootstrap!$B$39:$B$59,1)+1)-INDEX(Bootstrap!$D$39:$D$59,MATCH((($H8-MarketData!$B$4)/360),Bootstrap!$B$39:$B$59,1)))*(((($H8-MarketData!$B$4)/360))-INDEX(Bootstrap!$B$39:$B$59,MATCH((($H8-MarketData!$B$4)/360),Bootstrap!$B$39:$B$59,1)))/(INDEX(Bootstrap!$B$39:$B$59,MATCH((($H8-MarketData!$B$4)/360),Bootstrap!$B$39:$B$59,1)+1)-INDEX(Bootstrap!$B$39:$B$59,MATCH((($H8-MarketData!$B$4)/360),Bootstrap!$B$39:$B$59,1)))) -> 0.98972781 | K8: =EXP(INDEX(Bootstrap!$D$39:$D$59,MATCH((($I8-MarketData!$B$4)/360),Bootstrap!$B$39:$B$59,1))+(INDEX(Bootstrap!$D$39:$D$59,MATCH((($I8-MarketData!$B$4)/360),Bootstrap!$B$39:$B$59,1)+1)-INDEX(Bootstrap!$D$39:$D$59,MATCH((($I8-MarketData!$B$4)/360),Bootstrap!$B$39:$B$59,1)))*(((($I8-MarketData!$B$4)/360))-INDEX(Bootstrap!$B$39:$B$59,MATCH((($I8-MarketData!$B$4)/360),Bootstrap!$B$39:$B$59,1)))/(INDEX(Bootstrap!$B$39:$B$59,MATCH((($I8-MarketData!$B$4)/360),Bootstrap!$B$39:$B$59,1)+1)-INDEX(Bootstrap!$B$39:$B$59,MATCH((($I8-MarketData!$B$4)/360),Bootstrap!$B$39:$B$59,1)))) -> 0.98677428 | L8: =(J8/K8-1)/G8 -> 0.037155914 | M8: =MarketData!$C$54 -> 0.037161226 | N8: =(L8-M8)*10000 -> -0.0531181
A9: =MarketData!$A$55 -> 46315 | B9: =(A9-MarketData!$B$4)/360 -> 0.38333333 | C9: =EXP(INDEX(Bootstrap!$D$39:$D$59,MATCH($B9,Bootstrap!$B$39:$B$59,1))+(INDEX(Bootstrap!$D$39:$D$59,MATCH($B9,Bootstrap!$B$39:$B$59,1)+1)-INDEX(Bootstrap!$D$39:$D$59,MATCH($B9,Bootstrap!$B$39:$B$59,1)))*(($B9)-INDEX(Bootstrap!$B$39:$B$59,MATCH($B9,Bootstrap!$B$39:$B$59,1)))/(INDEX(Bootstrap!$B$39:$B$59,MATCH($B9,Bootstrap!$B$39:$B$59,1)+1)-INDEX(Bootstrap!$B$39:$B$59,MATCH($B9,Bootstrap!$B$39:$B$59,1)))) -> 0.98606149 | D9: =MarketData!$B$55 -> 0.98608283 | E9: =(LN(D9)-LN(C9))/B9*10000 -> 0.5644544 | F9: =A10 -> 46346 | G9: =(F9-A9)/360 -> 0.086111111 | H9: =WORKDAY(A9,-5) -> 46308 | I9: =WORKDAY(F9,-5) -> 46339 | J9: =EXP(INDEX(Bootstrap!$D$39:$D$59,MATCH((($H9-MarketData!$B$4)/360),Bootstrap!$B$39:$B$59,1))+(INDEX(Bootstrap!$D$39:$D$59,MATCH((($H9-MarketData!$B$4)/360),Bootstrap!$B$39:$B$59,1)+1)-INDEX(Bootstrap!$D$39:$D$59,MATCH((($H9-MarketData!$B$4)/360),Bootstrap!$B$39:$B$59,1)))*(((($H9-MarketData!$B$4)/360))-INDEX(Bootstrap!$B$39:$B$59,MATCH((($H9-MarketData!$B$4)/360),Bootstrap!$B$39:$B$59,1)))/(INDEX(Bootstrap!$B$39:$B$59,MATCH((($H9-MarketData!$B$4)/360),Bootstrap!$B$39:$B$59,1)+1)-INDEX(Bootstrap!$B$39:$B$59,MATCH((($H9-MarketData!$B$4)/360),Bootstrap!$B$39:$B$59,1)))) -> 0.98677428 | K9: =EXP(INDEX(Bootstrap!$D$39:$D$59,MATCH((($I9-MarketData!$B$4)/360),Bootstrap!$B$39:$B$59,1))+(INDEX(Bootstrap!$D$39:$D$59,MATCH((($I9-MarketData!$B$4)/360),Bootstrap!$B$39:$B$59,1)+1)-INDEX(Bootstrap!$D$39:$D$59,MATCH((($I9-MarketData!$B$4)/360),Bootstrap!$B$39:$B$59,1)))*(((($I9-MarketData!$B$4)/360))-INDEX(Bootstrap!$B$39:$B$59,MATCH((($I9-MarketData!$B$4)/360),Bootstrap!$B$39:$B$59,1)))/(INDEX(Bootstrap!$B$39:$B$59,MATCH((($I9-MarketData!$B$4)/360),Bootstrap!$B$39:$B$59,1)+1)-INDEX(Bootstrap!$B$39:$B$59,MATCH((($I9-MarketData!$B$4)/360),Bootstrap!$B$39:$B$59,1)))) -> 0.98360377 | L9: =(J9/K9-1)/G9 -> 0.037432573 | M9: =MarketData!$C$55 -> 0.037432255 | N9: =(L9-M9)*10000 -> 0.0031762045
A10: =MarketData!$A$56 -> 46346 | B10: =(A10-MarketData!$B$4)/360 -> 0.46944444 | C10: =EXP(INDEX(Bootstrap!$D$39:$D$59,MATCH($B10,Bootstrap!$B$39:$B$59,1))+(INDEX(Bootstrap!$D$39:$D$59,MATCH($B10,Bootstrap!$B$39:$B$59,1)+1)-INDEX(Bootstrap!$D$39:$D$59,MATCH($B10,Bootstrap!$B$39:$B$59,1)))*(($B10)-INDEX(Bootstrap!$B$39:$B$59,MATCH($B10,Bootstrap!$B$39:$B$59,1)))/(INDEX(Bootstrap!$B$39:$B$59,MATCH($B10,Bootstrap!$B$39:$B$59,1)+1)-INDEX(Bootstrap!$B$39:$B$59,MATCH($B10,Bootstrap!$B$39:$B$59,1)))) -> 0.98288498 | D10: =MarketData!$B$56 -> 0.98290625 | E10: =(LN(D10)-LN(C10))/B10*10000 -> 0.46092555 | F10: =A11 -> 46377 | G10: =(F10-A10)/360 -> 0.086111111 | H10: =WORKDAY(A10,-5) -> 46339 | I10: =WORKDAY(F10,-5) -> 46370 | J10: =EXP(INDEX(Bootstrap!$D$39:$D$59,MATCH((($H10-MarketData!$B$4)/360),Bootstrap!$B$39:$B$59,1))+(INDEX(Bootstrap!$D$39:$D$59,MATCH((($H10-MarketData!$B$4)/360),Bootstrap!$B$39:$B$59,1)+1)-INDEX(Bootstrap!$D$39:$D$59,MATCH((($H10-MarketData!$B$4)/360),Bootstrap!$B$39:$B$59,1)))*(((($H10-MarketData!$B$4)/360))-INDEX(Bootstrap!$B$39:$B$59,MATCH((($H10-MarketData!$B$4)/360),Bootstrap!$B$39:$B$59,1)))/(INDEX(Bootstrap!$B$39:$B$59,MATCH((($H10-MarketData!$B$4)/360),Bootstrap!$B$39:$B$59,1)+1)-INDEX(Bootstrap!$B$39:$B$59,MATCH((($H10-MarketData!$B$4)/360),Bootstrap!$B$39:$B$59,1)))) -> 0.98360377 | K10: =EXP(INDEX(Bootstrap!$D$39:$D$59,MATCH((($I10-MarketData!$B$4)/360),Bootstrap!$B$39:$B$59,1))+(INDEX(Bootstrap!$D$39:$D$59,MATCH((($I10-MarketData!$B$4)/360),Bootstrap!$B$39:$B$59,1)+1)-INDEX(Bootstrap!$D$39:$D$59,MATCH((($I10-MarketData!$B$4)/360),Bootstrap!$B$39:$B$59,1)))*(((($I10-MarketData!$B$4)/360))-INDEX(Bootstrap!$B$39:$B$59,MATCH((($I10-MarketData!$B$4)/360),Bootstrap!$B$39:$B$59,1)))/(INDEX(Bootstrap!$B$39:$B$59,MATCH((($I10-MarketData!$B$4)/360),Bootstrap!$B$39:$B$59,1)+1)-INDEX(Bootstrap!$B$39:$B$59,MATCH((($I10-MarketData!$B$4)/360),Bootstrap!$B$39:$B$59,1)))) -> 0.98041419 | L10: =(J10/K10-1)/G10 -> 0.037780236 | M10: =MarketData!$C$56 -> 0.03774029 | N10: =(L10-M10)*10000 -> 0.39945714
A11: =MarketData!$A$57 -> 46377 | B11: =(A11-MarketData!$B$4)/360 -> 0.55555556 | C11: =EXP(INDEX(Bootstrap!$D$39:$D$59,MATCH($B11,Bootstrap!$B$39:$B$59,1))+(INDEX(Bootstrap!$D$39:$D$59,MATCH($B11,Bootstrap!$B$39:$B$59,1)+1)-INDEX(Bootstrap!$D$39:$D$59,MATCH($B11,Bootstrap!$B$39:$B$59,1)))*(($B11)-INDEX(Bootstrap!$B$39:$B$59,MATCH($B11,Bootstrap!$B$39:$B$59,1)))/(INDEX(Bootstrap!$B$39:$B$59,MATCH($B11,Bootstrap!$B$39:$B$59,1)+1)-INDEX(Bootstrap!$B$39:$B$59,MATCH($B11,Bootstrap!$B$39:$B$59,1)))) -> 0.97967965 | D11: =MarketData!$B$57 -> 0.97971001 | E11: =(LN(D11)-LN(C11))/B11*10000 -> 0.55784127 | F11: =A12 -> 46407 | G11: =(F11-A11)/360 -> 0.083333333 | H11: =WORKDAY(A11,-5) -> 46370 | I11: =WORKDAY(F11,-5) -> 46400 | J11: =EXP(INDEX(Bootstrap!$D$39:$D$59,MATCH((($H11-MarketData!$B$4)/360),Bootstrap!$B$39:$B$59,1))+(INDEX(Bootstrap!$D$39:$D$59,MATCH((($H11-MarketData!$B$4)/360),Bootstrap!$B$39:$B$59,1)+1)-INDEX(Bootstrap!$D$39:$D$59,MATCH((($H11-MarketData!$B$4)/360),Bootstrap!$B$39:$B$59,1)))*(((($H11-MarketData!$B$4)/360))-INDEX(Bootstrap!$B$39:$B$59,MATCH((($H11-MarketData!$B$4)/360),Bootstrap!$B$39:$B$59,1)))/(INDEX(Bootstrap!$B$39:$B$59,MATCH((($H11-MarketData!$B$4)/360),Bootstrap!$B$39:$B$59,1)+1)-INDEX(Bootstrap!$B$39:$B$59,MATCH((($H11-MarketData!$B$4)/360),Bootstrap!$B$39:$B$59,1)))) -> 0.98041419 | K11: =EXP(INDEX(Bootstrap!$D$39:$D$59,MATCH((($I11-MarketData!$B$4)/360),Bootstrap!$B$39:$B$59,1))+(INDEX(Bootstrap!$D$39:$D$59,MATCH((($I11-MarketData!$B$4)/360),Bootstrap!$B$39:$B$59,1)+1)-INDEX(Bootstrap!$D$39:$D$59,MATCH((($I11-MarketData!$B$4)/360),Bootstrap!$B$39:$B$59,1)))*(((($I11-MarketData!$B$4)/360))-INDEX(Bootstrap!$B$39:$B$59,MATCH((($I11-MarketData!$B$4)/360),Bootstrap!$B$39:$B$59,1)))/(INDEX(Bootstrap!$B$39:$B$59,MATCH((($I11-MarketData!$B$4)/360),Bootstrap!$B$39:$B$59,1)+1)-INDEX(Bootstrap!$B$39:$B$59,MATCH((($I11-MarketData!$B$4)/360),Bootstrap!$B$39:$B$59,1)))) -> 0.97727001 | L11: =(J11/K11-1)/G11 -> 0.038607681 | M11: =MarketData!$C$57 -> 0.038633655 | N11: =(L11-M11)*10000 -> -0.25973289
A12: =MarketData!$A$58 -> 46407 | B12: =(A12-MarketData!$B$4)/360 -> 0.63888889 | C12: =EXP(INDEX(Bootstrap!$D$39:$D$59,MATCH($B12,Bootstrap!$B$39:$B$59,1))+(INDEX(Bootstrap!$D$39:$D$59,MATCH($B12,Bootstrap!$B$39:$B$59,1)+1)-INDEX(Bootstrap!$D$39:$D$59,MATCH($B12,Bootstrap!$B$39:$B$59,1)))*(($B12)-INDEX(Bootstrap!$B$39:$B$59,MATCH($B12,Bootstrap!$B$39:$B$59,1)))/(INDEX(Bootstrap!$B$39:$B$59,MATCH($B12,Bootstrap!$B$39:$B$59,1)+1)-INDEX(Bootstrap!$B$39:$B$59,MATCH($B12,Bootstrap!$B$39:$B$59,1)))) -> 0.97653782 | D12: =MarketData!$B$58 -> 0.97655231 | E12: =(LN(D12)-LN(C12))/B12*10000 -> 0.23219393 | F12: =A13 -> 46440 | G12: =(F12-A12)/360 -> 0.091666667 | H12: =WORKDAY(A12,-5) -> 46400 | I12: =WORKDAY(F12,-5) -> 46433 | J12: =EXP(INDEX(Bootstrap!$D$39:$D$59,MATCH((($H12-MarketData!$B$4)/360),Bootstrap!$B$39:$B$59,1))+(INDEX(Bootstrap!$D$39:$D$59,MATCH((($H12-MarketData!$B$4)/360),Bootstrap!$B$39:$B$59,1)+1)-INDEX(Bootstrap!$D$39:$D$59,MATCH((($H12-MarketData!$B$4)/360),Bootstrap!$B$39:$B$59,1)))*(((($H12-MarketData!$B$4)/360))-INDEX(Bootstrap!$B$39:$B$59,MATCH((($H12-MarketData!$B$4)/360),Bootstrap!$B$39:$B$59,1)))/(INDEX(Bootstrap!$B$39:$B$59,MATCH((($H12-MarketData!$B$4)/360),Bootstrap!$B$39:$B$59,1)+1)-INDEX(Bootstrap!$B$39:$B$59,MATCH((($H12-MarketData!$B$4)/360),Bootstrap!$B$39:$B$59,1)))) -> 0.97727001 | K12: =EXP(INDEX(Bootstrap!$D$39:$D$59,MATCH((($I12-MarketData!$B$4)/360),Bootstrap!$B$39:$B$59,1))+(INDEX(Bootstrap!$D$39:$D$59,MATCH((($I12-MarketData!$B$4)/360),Bootstrap!$B$39:$B$59,1)+1)-INDEX(Bootstrap!$D$39:$D$59,MATCH((($I12-MarketData!$B$4)/360),Bootstrap!$B$39:$B$59,1)))*(((($I12-MarketData!$B$4)/360))-INDEX(Bootstrap!$B$39:$B$59,MATCH((($I12-MarketData!$B$4)/360),Bootstrap!$B$39:$B$59,1)))/(INDEX(Bootstrap!$B$39:$B$59,MATCH((($I12-MarketData!$B$4)/360),Bootstrap!$B$39:$B$59,1)+1)-INDEX(Bootstrap!$B$39:$B$59,MATCH((($I12-MarketData!$B$4)/360),Bootstrap!$B$39:$B$59,1)))) -> 0.97382335 | L12: =(J12/K12-1)/G12 -> 0.038610619 | M12: =MarketData!$C$58 -> 0.038470168 | N12: =(L12-M12)*10000 -> 1.4045054
A13: =MarketData!$A$59 -> 46440 | B13: =(A13-MarketData!$B$4)/360 -> 0.73055556 | C13: =EXP(INDEX(Bootstrap!$D$39:$D$59,MATCH($B13,Bootstrap!$B$39:$B$59,1))+(INDEX(Bootstrap!$D$39:$D$59,MATCH($B13,Bootstrap!$B$39:$B$59,1)+1)-INDEX(Bootstrap!$D$39:$D$59,MATCH($B13,Bootstrap!$B$39:$B$59,1)))*(($B13)-INDEX(Bootstrap!$B$39:$B$59,MATCH($B13,Bootstrap!$B$39:$B$59,1)))/(INDEX(Bootstrap!$B$39:$B$59,MATCH($B13,Bootstrap!$B$39:$B$59,1)+1)-INDEX(Bootstrap!$B$39:$B$59,MATCH($B13,Bootstrap!$B$39:$B$59,1)))) -> 0.97309386 | D13: =MarketData!$B$59 -> 0.97311492 | E13: =(LN(D13)-LN(C13))/B13*10000 -> 0.29618492 | F13: =A14 -> 46468 | G13: =(F13-A13)/360 -> 0.077777778 | H13: =WORKDAY(A13,-5) -> 46433 | I13: =WORKDAY(F13,-5) -> 46461 | J13: =EXP(INDEX(Bootstrap!$D$39:$D$59,MATCH((($H13-MarketData!$B$4)/360),Bootstrap!$B$39:$B$59,1))+(INDEX(Bootstrap!$D$39:$D$59,MATCH((($H13-MarketData!$B$4)/360),Bootstrap!$B$39:$B$59,1)+1)-INDEX(Bootstrap!$D$39:$D$59,MATCH((($H13-MarketData!$B$4)/360),Bootstrap!$B$39:$B$59,1)))*(((($H13-MarketData!$B$4)/360))-INDEX(Bootstrap!$B$39:$B$59,MATCH((($H13-MarketData!$B$4)/360),Bootstrap!$B$39:$B$59,1)))/(INDEX(Bootstrap!$B$39:$B$59,MATCH((($H13-MarketData!$B$4)/360),Bootstrap!$B$39:$B$59,1)+1)-INDEX(Bootstrap!$B$39:$B$59,MATCH((($H13-MarketData!$B$4)/360),Bootstrap!$B$39:$B$59,1)))) -> 0.97382335 | K13: =EXP(INDEX(Bootstrap!$D$39:$D$59,MATCH((($I13-MarketData!$B$4)/360),Bootstrap!$B$39:$B$59,1))+(INDEX(Bootstrap!$D$39:$D$59,MATCH((($I13-MarketData!$B$4)/360),Bootstrap!$B$39:$B$59,1)+1)-INDEX(Bootstrap!$D$39:$D$59,MATCH((($I13-MarketData!$B$4)/360),Bootstrap!$B$39:$B$59,1)))*(((($I13-MarketData!$B$4)/360))-INDEX(Bootstrap!$B$39:$B$59,MATCH((($I13-MarketData!$B$4)/360),Bootstrap!$B$39:$B$59,1)))/(INDEX(Bootstrap!$B$39:$B$59,MATCH((($I13-MarketData!$B$4)/360),Bootstrap!$B$39:$B$59,1)+1)-INDEX(Bootstrap!$B$39:$B$59,MATCH((($I13-MarketData!$B$4)/360),Bootstrap!$B$39:$B$59,1)))) -> 0.97090865 | L13: =(J13/K13-1)/G13 -> 0.038597559 | M13: =MarketData!$C$59 -> 0.038597781 | N13: =(L13-M13)*10000 -> -0.0022171085
A14: =MarketData!$A$60 -> 46468 | B14: =(A14-MarketData!$B$4)/360 -> 0.80833333 | C14: =EXP(INDEX(Bootstrap!$D$39:$D$59,MATCH($B14,Bootstrap!$B$39:$B$59,1))+(INDEX(Bootstrap!$D$39:$D$59,MATCH($B14,Bootstrap!$B$39:$B$59,1)+1)-INDEX(Bootstrap!$D$39:$D$59,MATCH($B14,Bootstrap!$B$39:$B$59,1)))*(($B14)-INDEX(Bootstrap!$B$39:$B$59,MATCH($B14,Bootstrap!$B$39:$B$59,1)))/(INDEX(Bootstrap!$B$39:$B$59,MATCH($B14,Bootstrap!$B$39:$B$59,1)+1)-INDEX(Bootstrap!$B$39:$B$59,MATCH($B14,Bootstrap!$B$39:$B$59,1)))) -> 0.97017429 | D14: =MarketData!$B$60 -> 0.97019528 | E14: =(LN(D14)-LN(C14))/B14*10000 -> 0.26767931 | F14: =A15 -> 46497 | G14: =(F14-A14)/360 -> 0.080555556 | H14: =WORKDAY(A14,-5) -> 46461 | I14: =WORKDAY(F14,-5) -> 46490 | J14: =EXP(INDEX(Bootstrap!$D$39:$D$59,MATCH((($H14-MarketData!$B$4)/360),Bootstrap!$B$39:$B$59,1))+(INDEX(Bootstrap!$D$39:$D$59,MATCH((($H14-MarketData!$B$4)/360),Bootstrap!$B$39:$B$59,1)+1)-INDEX(Bootstrap!$D$39:$D$59,MATCH((($H14-MarketData!$B$4)/360),Bootstrap!$B$39:$B$59,1)))*(((($H14-MarketData!$B$4)/360))-INDEX(Bootstrap!$B$39:$B$59,MATCH((($H14-MarketData!$B$4)/360),Bootstrap!$B$39:$B$59,1)))/(INDEX(Bootstrap!$B$39:$B$59,MATCH((($H14-MarketData!$B$4)/360),Bootstrap!$B$39:$B$59,1)+1)-INDEX(Bootstrap!$B$39:$B$59,MATCH((($H14-MarketData!$B$4)/360),Bootstrap!$B$39:$B$59,1)))) -> 0.97090865 | K14: =EXP(INDEX(Bootstrap!$D$39:$D$59,MATCH((($I14-MarketData!$B$4)/360),Bootstrap!$B$39:$B$59,1))+(INDEX(Bootstrap!$D$39:$D$59,MATCH((($I14-MarketData!$B$4)/360),Bootstrap!$B$39:$B$59,1)+1)-INDEX(Bootstrap!$D$39:$D$59,MATCH((($I14-MarketData!$B$4)/360),Bootstrap!$B$39:$B$59,1)))*(((($I14-MarketData!$B$4)/360))-INDEX(Bootstrap!$B$39:$B$59,MATCH((($I14-MarketData!$B$4)/360),Bootstrap!$B$39:$B$59,1)))/(INDEX(Bootstrap!$B$39:$B$59,MATCH((($I14-MarketData!$B$4)/360),Bootstrap!$B$39:$B$59,1)+1)-INDEX(Bootstrap!$B$39:$B$59,MATCH((($I14-MarketData!$B$4)/360),Bootstrap!$B$39:$B$59,1)))) -> 0.9678533 | L14: =(J14/K14-1)/G14 -> 0.03918827 | M14: =MarketData!$C$60 -> 0.039187753 | N14: =(L14-M14)*10000 -> 0.0051641493
A15: =MarketData!$A$61 -> 46497 | B15: =(A15-MarketData!$B$4)/360 -> 0.88888889 | C15: =EXP(INDEX(Bootstrap!$D$39:$D$59,MATCH($B15,Bootstrap!$B$39:$B$59,1))+(INDEX(Bootstrap!$D$39:$D$59,MATCH($B15,Bootstrap!$B$39:$B$59,1)+1)-INDEX(Bootstrap!$D$39:$D$59,MATCH($B15,Bootstrap!$B$39:$B$59,1)))*(($B15)-INDEX(Bootstrap!$B$39:$B$59,MATCH($B15,Bootstrap!$B$39:$B$59,1)))/(INDEX(Bootstrap!$B$39:$B$59,MATCH($B15,Bootstrap!$B$39:$B$59,1)+1)-INDEX(Bootstrap!$B$39:$B$59,MATCH($B15,Bootstrap!$B$39:$B$59,1)))) -> 0.96711597 | D15: =MarketData!$B$61 -> 0.9671369 | E15: =(LN(D15)-LN(C15))/B15*10000 -> 0.24342326 | F15: =A16 -> 46527 | G15: =(F15-A15)/360 -> 0.083333333 | H15: =WORKDAY(A15,-5) -> 46490 | I15: =WORKDAY(F15,-5) -> 46520 | J15: =EXP(INDEX(Bootstrap!$D$39:$D$59,MATCH((($H15-MarketData!$B$4)/360),Bootstrap!$B$39:$B$59,1))+(INDEX(Bootstrap!$D$39:$D$59,MATCH((($H15-MarketData!$B$4)/360),Bootstrap!$B$39:$B$59,1)+1)-INDEX(Bootstrap!$D$39:$D$59,MATCH((($H15-MarketData!$B$4)/360),Bootstrap!$B$39:$B$59,1)))*(((($H15-MarketData!$B$4)/360))-INDEX(Bootstrap!$B$39:$B$59,MATCH((($H15-MarketData!$B$4)/360),Bootstrap!$B$39:$B$59,1)))/(INDEX(Bootstrap!$B$39:$B$59,MATCH((($H15-MarketData!$B$4)/360),Bootstrap!$B$39:$B$59,1)+1)-INDEX(Bootstrap!$B$39:$B$59,MATCH((($H15-MarketData!$B$4)/360),Bootstrap!$B$39:$B$59,1)))) -> 0.9678533 | K15: =EXP(INDEX(Bootstrap!$D$39:$D$59,MATCH((($I15-MarketData!$B$4)/360),Bootstrap!$B$39:$B$59,1))+(INDEX(Bootstrap!$D$39:$D$59,MATCH((($I15-MarketData!$B$4)/360),Bootstrap!$B$39:$B$59,1)+1)-INDEX(Bootstrap!$D$39:$D$59,MATCH((($I15-MarketData!$B$4)/360),Bootstrap!$B$39:$B$59,1)))*(((($I15-MarketData!$B$4)/360))-INDEX(Bootstrap!$B$39:$B$59,MATCH((($I15-MarketData!$B$4)/360),Bootstrap!$B$39:$B$59,1)))/(INDEX(Bootstrap!$B$39:$B$59,MATCH((($I15-MarketData!$B$4)/360),Bootstrap!$B$39:$B$59,1)+1)-INDEX(Bootstrap!$B$39:$B$59,MATCH((($I15-MarketData!$B$4)/360),Bootstrap!$B$39:$B$59,1)))) -> 0.96467333 | L15: =(J15/K15-1)/G15 -> 0.039557065 | M15: =MarketData!$C$61 -> 0.039557065 | N15: =(L15-M15)*10000 -> 9.6726169e-08
A16: =MarketData!$A$62 -> 46527 | B16: =(A16-MarketData!$B$4)/360 -> 0.97222222 | C16: =EXP(INDEX(Bootstrap!$D$39:$D$59,MATCH($B16,Bootstrap!$B$39:$B$59,1))+(INDEX(Bootstrap!$D$39:$D$59,MATCH($B16,Bootstrap!$B$39:$B$59,1)+1)-INDEX(Bootstrap!$D$39:$D$59,MATCH($B16,Bootstrap!$B$39:$B$59,1)))*(($B16)-INDEX(Bootstrap!$B$39:$B$59,MATCH($B16,Bootstrap!$B$39:$B$59,1)))/(INDEX(Bootstrap!$B$39:$B$59,MATCH($B16,Bootstrap!$B$39:$B$59,1)+1)-INDEX(Bootstrap!$B$39:$B$59,MATCH($B16,Bootstrap!$B$39:$B$59,1)))) -> 0.96392647 | D16: =MarketData!$B$62 -> 0.96394732 | E16: =(LN(D16)-LN(C16))/B16*10000 -> 0.22255877 | F16: =A17 -> 46559 | G16: =(F16-A16)/360 -> 0.088888889 | H16: =WORKDAY(A16,-5) -> 46520 | I16: =WORKDAY(F16,-5) -> 46552 | J16: =EXP(INDEX(Bootstrap!$D$39:$D$59,MATCH((($H16-MarketData!$B$4)/360),Bootstrap!$B$39:$B$59,1))+(INDEX(Bootstrap!$D$39:$D$59,MATCH((($H16-MarketData!$B$4)/360),Bootstrap!$B$39:$B$59,1)+1)-INDEX(Bootstrap!$D$39:$D$59,MATCH((($H16-MarketData!$B$4)/360),Bootstrap!$B$39:$B$59,1)))*(((($H16-MarketData!$B$4)/360))-INDEX(Bootstrap!$B$39:$B$59,MATCH((($H16-MarketData!$B$4)/360),Bootstrap!$B$39:$B$59,1)))/(INDEX(Bootstrap!$B$39:$B$59,MATCH((($H16-MarketData!$B$4)/360),Bootstrap!$B$39:$B$59,1)+1)-INDEX(Bootstrap!$B$39:$B$59,MATCH((($H16-MarketData!$B$4)/360),Bootstrap!$B$39:$B$59,1)))) -> 0.96467333 | K16: =EXP(INDEX(Bootstrap!$D$39:$D$59,MATCH((($I16-MarketData!$B$4)/360),Bootstrap!$B$39:$B$59,1))+(INDEX(Bootstrap!$D$39:$D$59,MATCH((($I16-MarketData!$B$4)/360),Bootstrap!$B$39:$B$59,1)+1)-INDEX(Bootstrap!$D$39:$D$59,MATCH((($I16-MarketData!$B$4)/360),Bootstrap!$B$39:$B$59,1)))*(((($I16-MarketData!$B$4)/360))-INDEX(Bootstrap!$B$39:$B$59,MATCH((($I16-MarketData!$B$4)/360),Bootstrap!$B$39:$B$59,1)))/(INDEX(Bootstrap!$B$39:$B$59,MATCH((($I16-MarketData!$B$4)/360),Bootstrap!$B$39:$B$59,1)+1)-INDEX(Bootstrap!$B$39:$B$59,MATCH((($I16-MarketData!$B$4)/360),Bootstrap!$B$39:$B$59,1)))) -> 0.96126295 | L16: =(J16/K16-1)/G16 -> 0.039912866 | M16: =MarketData!$C$62 -> 0.039907075 | N16: =(L16-M16)*10000 -> 0.057908007
A17: =MarketData!$A$63 -> 46559 | B17: =(A17-MarketData!$B$4)/360 -> 1.0611111 | C17: =EXP(INDEX(Bootstrap!$D$39:$D$59,MATCH($B17,Bootstrap!$B$39:$B$59,1))+(INDEX(Bootstrap!$D$39:$D$59,MATCH($B17,Bootstrap!$B$39:$B$59,1)+1)-INDEX(Bootstrap!$D$39:$D$59,MATCH($B17,Bootstrap!$B$39:$B$59,1)))*(($B17)-INDEX(Bootstrap!$B$39:$B$59,MATCH($B17,Bootstrap!$B$39:$B$59,1)))/(INDEX(Bootstrap!$B$39:$B$59,MATCH($B17,Bootstrap!$B$39:$B$59,1)+1)-INDEX(Bootstrap!$B$39:$B$59,MATCH($B17,Bootstrap!$B$39:$B$59,1)))) -> 0.96051912 | D17: =MarketData!$B$63 -> 0.96053938 | E17: =(LN(D17)-LN(C17))/B17*10000 -> 0.19880759 | F17: =A18 -> 46588 | G17: =(F17-A17)/360 -> 0.080555556 | H17: =WORKDAY(A17,-5) -> 46552 | I17: =WORKDAY(F17,-5) -> 46581 | J17: =EXP(INDEX(Bootstrap!$D$39:$D$59,MATCH((($H17-MarketData!$B$4)/360),Bootstrap!$B$39:$B$59,1))+(INDEX(Bootstrap!$D$39:$D$59,MATCH((($H17-MarketData!$B$4)/360),Bootstrap!$B$39:$B$59,1)+1)-INDEX(Bootstrap!$D$39:$D$59,MATCH((($H17-MarketData!$B$4)/360),Bootstrap!$B$39:$B$59,1)))*(((($H17-MarketData!$B$4)/360))-INDEX(Bootstrap!$B$39:$B$59,MATCH((($H17-MarketData!$B$4)/360),Bootstrap!$B$39:$B$59,1)))/(INDEX(Bootstrap!$B$39:$B$59,MATCH((($H17-MarketData!$B$4)/360),Bootstrap!$B$39:$B$59,1)+1)-INDEX(Bootstrap!$B$39:$B$59,MATCH((($H17-MarketData!$B$4)/360),Bootstrap!$B$39:$B$59,1)))) -> 0.96126295 | K17: =EXP(INDEX(Bootstrap!$D$39:$D$59,MATCH((($I17-MarketData!$B$4)/360),Bootstrap!$B$39:$B$59,1))+(INDEX(Bootstrap!$D$39:$D$59,MATCH((($I17-MarketData!$B$4)/360),Bootstrap!$B$39:$B$59,1)+1)-INDEX(Bootstrap!$D$39:$D$59,MATCH((($I17-MarketData!$B$4)/360),Bootstrap!$B$39:$B$59,1)))*(((($I17-MarketData!$B$4)/360))-INDEX(Bootstrap!$B$39:$B$59,MATCH((($I17-MarketData!$B$4)/360),Bootstrap!$B$39:$B$59,1)))/(INDEX(Bootstrap!$B$39:$B$59,MATCH((($I17-MarketData!$B$4)/360),Bootstrap!$B$39:$B$59,1)+1)-INDEX(Bootstrap!$B$39:$B$59,MATCH((($I17-MarketData!$B$4)/360),Bootstrap!$B$39:$B$59,1)))) -> 0.95818743 | L17: =(J17/K17-1)/G17 -> 0.039844897 | M17: =MarketData!$C$63 -> 0.03990391 | N17: =(L17-M17)*10000 -> -0.59013569
A18: =MarketData!$A$64 -> 46588 | B18: =(A18-MarketData!$B$4)/360 -> 1.1416667 | C18: =EXP(INDEX(Bootstrap!$D$39:$D$59,MATCH($B18,Bootstrap!$B$39:$B$59,1))+(INDEX(Bootstrap!$D$39:$D$59,MATCH($B18,Bootstrap!$B$39:$B$59,1)+1)-INDEX(Bootstrap!$D$39:$D$59,MATCH($B18,Bootstrap!$B$39:$B$59,1)))*(($B18)-INDEX(Bootstrap!$B$39:$B$59,MATCH($B18,Bootstrap!$B$39:$B$59,1)))/(INDEX(Bootstrap!$B$39:$B$59,MATCH($B18,Bootstrap!$B$39:$B$59,1)+1)-INDEX(Bootstrap!$B$39:$B$59,MATCH($B18,Bootstrap!$B$39:$B$59,1)))) -> 0.95744672 | D18: =MarketData!$B$64 -> 0.95746285 | E18: =(LN(D18)-LN(C18))/B18*10000 -> 0.1475412 | F18: =A19 -> 46619 | G18: =(F18-A18)/360 -> 0.086111111 | H18: =WORKDAY(A18,-5) -> 46581 | I18: =WORKDAY(F18,-5) -> 46612 | J18: =EXP(INDEX(Bootstrap!$D$39:$D$59,MATCH((($H18-MarketData!$B$4)/360),Bootstrap!$B$39:$B$59,1))+(INDEX(Bootstrap!$D$39:$D$59,MATCH((($H18-MarketData!$B$4)/360),Bootstrap!$B$39:$B$59,1)+1)-INDEX(Bootstrap!$D$39:$D$59,MATCH((($H18-MarketData!$B$4)/360),Bootstrap!$B$39:$B$59,1)))*(((($H18-MarketData!$B$4)/360))-INDEX(Bootstrap!$B$39:$B$59,MATCH((($H18-MarketData!$B$4)/360),Bootstrap!$B$39:$B$59,1)))/(INDEX(Bootstrap!$B$39:$B$59,MATCH((($H18-MarketData!$B$4)/360),Bootstrap!$B$39:$B$59,1)+1)-INDEX(Bootstrap!$B$39:$B$59,MATCH((($H18-MarketData!$B$4)/360),Bootstrap!$B$39:$B$59,1)))) -> 0.95818743 | K18: =EXP(INDEX(Bootstrap!$D$39:$D$59,MATCH((($I18-MarketData!$B$4)/360),Bootstrap!$B$39:$B$59,1))+(INDEX(Bootstrap!$D$39:$D$59,MATCH((($I18-MarketData!$B$4)/360),Bootstrap!$B$39:$B$59,1)+1)-INDEX(Bootstrap!$D$39:$D$59,MATCH((($I18-MarketData!$B$4)/360),Bootstrap!$B$39:$B$59,1)))*(((($I18-MarketData!$B$4)/360))-INDEX(Bootstrap!$B$39:$B$59,MATCH((($I18-MarketData!$B$4)/360),Bootstrap!$B$39:$B$59,1)))/(INDEX(Bootstrap!$B$39:$B$59,MATCH((($I18-MarketData!$B$4)/360),Bootstrap!$B$39:$B$59,1)+1)-INDEX(Bootstrap!$B$39:$B$59,MATCH((($I18-MarketData!$B$4)/360),Bootstrap!$B$39:$B$59,1)))) -> 0.95491148 | L18: =(J18/K18-1)/G18 -> 0.039839592 | M18: =MarketData!$C$64 -> 0.03984468 | N18: =(L18-M18)*10000 -> -0.050874797
A19: =MarketData!$A$65 -> 46619 | B19: =(A19-MarketData!$B$4)/360 -> 1.2277778 | C19: =EXP(INDEX(Bootstrap!$D$39:$D$59,MATCH($B19,Bootstrap!$B$39:$B$59,1))+(INDEX(Bootstrap!$D$39:$D$59,MATCH($B19,Bootstrap!$B$39:$B$59,1)+1)-INDEX(Bootstrap!$D$39:$D$59,MATCH($B19,Bootstrap!$B$39:$B$59,1)))*(($B19)-INDEX(Bootstrap!$B$39:$B$59,MATCH($B19,Bootstrap!$B$39:$B$59,1)))/(INDEX(Bootstrap!$B$39:$B$59,MATCH($B19,Bootstrap!$B$39:$B$59,1)+1)-INDEX(Bootstrap!$B$39:$B$59,MATCH($B19,Bootstrap!$B$39:$B$59,1)))) -> 0.95417331 | D19: =MarketData!$B$65 -> 0.95419016 | E19: =(LN(D19)-LN(C19))/B19*10000 -> 0.14382736 | F19: =A20 -> 46650 | G19: =(F19-A19)/360 -> 0.086111111 | H19: =WORKDAY(A19,-5) -> 46612 | I19: =WORKDAY(F19,-5) -> 46643 | J19: =EXP(INDEX(Bootstrap!$D$39:$D$59,MATCH((($H19-MarketData!$B$4)/360),Bootstrap!$B$39:$B$59,1))+(INDEX(Bootstrap!$D$39:$D$59,MATCH((($H19-MarketData!$B$4)/360),Bootstrap!$B$39:$B$59,1)+1)-INDEX(Bootstrap!$D$39:$D$59,MATCH((($H19-MarketData!$B$4)/360),Bootstrap!$B$39:$B$59,1)))*(((($H19-MarketData!$B$4)/360))-INDEX(Bootstrap!$B$39:$B$59,MATCH((($H19-MarketData!$B$4)/360),Bootstrap!$B$39:$B$59,1)))/(INDEX(Bootstrap!$B$39:$B$59,MATCH((($H19-MarketData!$B$4)/360),Bootstrap!$B$39:$B$59,1)+1)-INDEX(Bootstrap!$B$39:$B$59,MATCH((($H19-MarketData!$B$4)/360),Bootstrap!$B$39:$B$59,1)))) -> 0.95491148 | K19: =EXP(INDEX(Bootstrap!$D$39:$D$59,MATCH((($I19-MarketData!$B$4)/360),Bootstrap!$B$39:$B$59,1))+(INDEX(Bootstrap!$D$39:$D$59,MATCH((($I19-MarketData!$B$4)/360),Bootstrap!$B$39:$B$59,1)+1)-INDEX(Bootstrap!$D$39:$D$59,MATCH((($I19-MarketData!$B$4)/360),Bootstrap!$B$39:$B$59,1)))*(((($I19-MarketData!$B$4)/360))-INDEX(Bootstrap!$B$39:$B$59,MATCH((($I19-MarketData!$B$4)/360),Bootstrap!$B$39:$B$59,1)))/(INDEX(Bootstrap!$B$39:$B$59,MATCH((($I19-MarketData!$B$4)/360),Bootstrap!$B$39:$B$59,1)+1)-INDEX(Bootstrap!$B$39:$B$59,MATCH((($I19-MarketData!$B$4)/360),Bootstrap!$B$39:$B$59,1)))) -> 0.95164674 | L19: =(J19/K19-1)/G19 -> 0.039839592 | M19: =MarketData!$C$65 -> 0.039780505 | N19: =(L19-M19)*10000 -> 0.5908782
A20: =MarketData!$A$66 -> 46650 | B20: =(A20-MarketData!$B$4)/360 -> 1.3138889 | C20: =EXP(INDEX(Bootstrap!$D$39:$D$59,MATCH($B20,Bootstrap!$B$39:$B$59,1))+(INDEX(Bootstrap!$D$39:$D$59,MATCH($B20,Bootstrap!$B$39:$B$59,1)+1)-INDEX(Bootstrap!$D$39:$D$59,MATCH($B20,Bootstrap!$B$39:$B$59,1)))*(($B20)-INDEX(Bootstrap!$B$39:$B$59,MATCH($B20,Bootstrap!$B$39:$B$59,1)))/(INDEX(Bootstrap!$B$39:$B$59,MATCH($B20,Bootstrap!$B$39:$B$59,1)+1)-INDEX(Bootstrap!$B$39:$B$59,MATCH($B20,Bootstrap!$B$39:$B$59,1)))) -> 0.95091188 | D20: =MarketData!$B$66 -> 0.95093372 | E20: =(LN(D20)-LN(C20))/B20*10000 -> 0.17482453 | F20: =A21 -> 46680 | G20: =(F20-A20)/360 -> 0.083333333 | H20: =WORKDAY(A20,-5) -> 46643 | I20: =WORKDAY(F20,-5) -> 46673 | J20: =EXP(INDEX(Bootstrap!$D$39:$D$59,MATCH((($H20-MarketData!$B$4)/360),Bootstrap!$B$39:$B$59,1))+(INDEX(Bootstrap!$D$39:$D$59,MATCH((($H20-MarketData!$B$4)/360),Bootstrap!$B$39:$B$59,1)+1)-INDEX(Bootstrap!$D$39:$D$59,MATCH((($H20-MarketData!$B$4)/360),Bootstrap!$B$39:$B$59,1)))*(((($H20-MarketData!$B$4)/360))-INDEX(Bootstrap!$B$39:$B$59,MATCH((($H20-MarketData!$B$4)/360),Bootstrap!$B$39:$B$59,1)))/(INDEX(Bootstrap!$B$39:$B$59,MATCH((($H20-MarketData!$B$4)/360),Bootstrap!$B$39:$B$59,1)+1)-INDEX(Bootstrap!$B$39:$B$59,MATCH((($H20-MarketData!$B$4)/360),Bootstrap!$B$39:$B$59,1)))) -> 0.95164674 | K20: =EXP(INDEX(Bootstrap!$D$39:$D$59,MATCH((($I20-MarketData!$B$4)/360),Bootstrap!$B$39:$B$59,1))+(INDEX(Bootstrap!$D$39:$D$59,MATCH((($I20-MarketData!$B$4)/360),Bootstrap!$B$39:$B$59,1)+1)-INDEX(Bootstrap!$D$39:$D$59,MATCH((($I20-MarketData!$B$4)/360),Bootstrap!$B$39:$B$59,1)))*(((($I20-MarketData!$B$4)/360))-INDEX(Bootstrap!$B$39:$B$59,MATCH((($I20-MarketData!$B$4)/360),Bootstrap!$B$39:$B$59,1)))/(INDEX(Bootstrap!$B$39:$B$59,MATCH((($I20-MarketData!$B$4)/360),Bootstrap!$B$39:$B$59,1)+1)-INDEX(Bootstrap!$B$39:$B$59,MATCH((($I20-MarketData!$B$4)/360),Bootstrap!$B$39:$B$59,1)))) -> 0.94850238 | L20: =(J20/K20-1)/G20 -> 0.039780839 | M20: =MarketData!$C$66 -> 0.039706712 | N20: =(L20-M20)*10000 -> 0.74126937
A21: =MarketData!$A$67 -> 46680 | B21: =(A21-MarketData!$B$4)/360 -> 1.3972222 | C21: =EXP(INDEX(Bootstrap!$D$39:$D$59,MATCH($B21,Bootstrap!$B$39:$B$59,1))+(INDEX(Bootstrap!$D$39:$D$59,MATCH($B21,Bootstrap!$B$39:$B$59,1)+1)-INDEX(Bootstrap!$D$39:$D$59,MATCH($B21,Bootstrap!$B$39:$B$59,1)))*(($B21)-INDEX(Bootstrap!$B$39:$B$59,MATCH($B21,Bootstrap!$B$39:$B$59,1)))/(INDEX(Bootstrap!$B$39:$B$59,MATCH($B21,Bootstrap!$B$39:$B$59,1)+1)-INDEX(Bootstrap!$B$39:$B$59,MATCH($B21,Bootstrap!$B$39:$B$59,1)))) -> 0.94777027 | D21: =MarketData!$B$67 -> 0.94779996 | E21: =(LN(D21)-LN(C21))/B21*10000 -> 0.22418001 | F21: =A22 -> 46713 | G21: =(F21-A21)/360 -> 0.091666667 | H21: =WORKDAY(A21,-5) -> 46673 | I21: =WORKDAY(F21,-5) -> 46706 | J21: =EXP(INDEX(Bootstrap!$D$39:$D$59,MATCH((($H21-MarketData!$B$4)/360),Bootstrap!$B$39:$B$59,1))+(INDEX(Bootstrap!$D$39:$D$59,MATCH((($H21-MarketData!$B$4)/360),Bootstrap!$B$39:$B$59,1)+1)-INDEX(Bootstrap!$D$39:$D$59,MATCH((($H21-MarketData!$B$4)/360),Bootstrap!$B$39:$B$59,1)))*(((($H21-MarketData!$B$4)/360))-INDEX(Bootstrap!$B$39:$B$59,MATCH((($H21-MarketData!$B$4)/360),Bootstrap!$B$39:$B$59,1)))/(INDEX(Bootstrap!$B$39:$B$59,MATCH((($H21-MarketData!$B$4)/360),Bootstrap!$B$39:$B$59,1)+1)-INDEX(Bootstrap!$B$39:$B$59,MATCH((($H21-MarketData!$B$4)/360),Bootstrap!$B$39:$B$59,1)))) -> 0.94850238 | K21: =EXP(INDEX(Bootstrap!$D$39:$D$59,MATCH((($I21-MarketData!$B$4)/360),Bootstrap!$B$39:$B$59,1))+(INDEX(Bootstrap!$D$39:$D$59,MATCH((($I21-MarketData!$B$4)/360),Bootstrap!$B$39:$B$59,1)+1)-INDEX(Bootstrap!$D$39:$D$59,MATCH((($I21-MarketData!$B$4)/360),Bootstrap!$B$39:$B$59,1)))*(((($I21-MarketData!$B$4)/360))-INDEX(Bootstrap!$B$39:$B$59,MATCH((($I21-MarketData!$B$4)/360),Bootstrap!$B$39:$B$59,1)))/(INDEX(Bootstrap!$B$39:$B$59,MATCH((($I21-MarketData!$B$4)/360),Bootstrap!$B$39:$B$59,1)+1)-INDEX(Bootstrap!$B$39:$B$59,MATCH((($I21-MarketData!$B$4)/360),Bootstrap!$B$39:$B$59,1)))) -> 0.94505594 | L21: =(J21/K21-1)/G21 -> 0.039783386 | M21: =MarketData!$C$67 -> 0.03957283 | N21: =(L21-M21)*10000 -> 2.105555
A22: =MarketData!$A$68 -> 46713 | B22: =(A22-MarketData!$B$4)/360 -> 1.4888889 | C22: =EXP(INDEX(Bootstrap!$D$39:$D$59,MATCH($B22,Bootstrap!$B$39:$B$59,1))+(INDEX(Bootstrap!$D$39:$D$59,MATCH($B22,Bootstrap!$B$39:$B$59,1)+1)-INDEX(Bootstrap!$D$39:$D$59,MATCH($B22,Bootstrap!$B$39:$B$59,1)))*(($B22)-INDEX(Bootstrap!$B$39:$B$59,MATCH($B22,Bootstrap!$B$39:$B$59,1)))/(INDEX(Bootstrap!$B$39:$B$59,MATCH($B22,Bootstrap!$B$39:$B$59,1)+1)-INDEX(Bootstrap!$B$39:$B$59,MATCH($B22,Bootstrap!$B$39:$B$59,1)))) -> 0.94432649 | D22: =MarketData!$B$68 -> 0.94437708 | E22: =(LN(D22)-LN(C22))/B22*10000 -> 0.35979942 | F22: =A23 -> 46741 | G22: =(F22-A22)/360 -> 0.077777778 | H22: =WORKDAY(A22,-5) -> 46706 | I22: =WORKDAY(F22,-5) -> 46734 | J22: =EXP(INDEX(Bootstrap!$D$39:$D$59,MATCH((($H22-MarketData!$B$4)/360),Bootstrap!$B$39:$B$59,1))+(INDEX(Bootstrap!$D$39:$D$59,MATCH((($H22-MarketData!$B$4)/360),Bootstrap!$B$39:$B$59,1)+1)-INDEX(Bootstrap!$D$39:$D$59,MATCH((($H22-MarketData!$B$4)/360),Bootstrap!$B$39:$B$59,1)))*(((($H22-MarketData!$B$4)/360))-INDEX(Bootstrap!$B$39:$B$59,MATCH((($H22-MarketData!$B$4)/360),Bootstrap!$B$39:$B$59,1)))/(INDEX(Bootstrap!$B$39:$B$59,MATCH((($H22-MarketData!$B$4)/360),Bootstrap!$B$39:$B$59,1)+1)-INDEX(Bootstrap!$B$39:$B$59,MATCH((($H22-MarketData!$B$4)/360),Bootstrap!$B$39:$B$59,1)))) -> 0.94505594 | K22: =EXP(INDEX(Bootstrap!$D$39:$D$59,MATCH((($I22-MarketData!$B$4)/360),Bootstrap!$B$39:$B$59,1))+(INDEX(Bootstrap!$D$39:$D$59,MATCH((($I22-MarketData!$B$4)/360),Bootstrap!$B$39:$B$59,1)+1)-INDEX(Bootstrap!$D$39:$D$59,MATCH((($I22-MarketData!$B$4)/360),Bootstrap!$B$39:$B$59,1)))*(((($I22-MarketData!$B$4)/360))-INDEX(Bootstrap!$B$39:$B$59,MATCH((($I22-MarketData!$B$4)/360),Bootstrap!$B$39:$B$59,1)))/(INDEX(Bootstrap!$B$39:$B$59,MATCH((($I22-MarketData!$B$4)/360),Bootstrap!$B$39:$B$59,1)+1)-INDEX(Bootstrap!$B$39:$B$59,MATCH((($I22-MarketData!$B$4)/360),Bootstrap!$B$39:$B$59,1)))) -> 0.94214151 | L22: =(J22/K22-1)/G22 -> 0.03977241 | M22: =MarketData!$C$68 -> 0.039423828 | N22: =(L22-M22)*10000 -> 3.4858236
A23: =MarketData!$A$69 -> 46741 | B23: =(A23-MarketData!$B$4)/360 -> 1.5666667 | C23: =EXP(INDEX(Bootstrap!$D$39:$D$59,MATCH($B23,Bootstrap!$B$39:$B$59,1))+(INDEX(Bootstrap!$D$39:$D$59,MATCH($B23,Bootstrap!$B$39:$B$59,1)+1)-INDEX(Bootstrap!$D$39:$D$59,MATCH($B23,Bootstrap!$B$39:$B$59,1)))*(($B23)-INDEX(Bootstrap!$B$39:$B$59,MATCH($B23,Bootstrap!$B$39:$B$59,1)))/(INDEX(Bootstrap!$B$39:$B$59,MATCH($B23,Bootstrap!$B$39:$B$59,1)+1)-INDEX(Bootstrap!$B$39:$B$59,MATCH($B23,Bootstrap!$B$39:$B$59,1)))) -> 0.94141744 | D23: =MarketData!$B$69 -> 0.94149399 | E23: =(LN(D23)-LN(C23))/B23*10000 -> 0.51895077 | F23: =A24 -> 46772 | G23: =(F23-A23)/360 -> 0.086111111 | H23: =WORKDAY(A23,-5) -> 46734 | I23: =WORKDAY(F23,-5) -> 46765 | J23: =EXP(INDEX(Bootstrap!$D$39:$D$59,MATCH((($H23-MarketData!$B$4)/360),Bootstrap!$B$39:$B$59,1))+(INDEX(Bootstrap!$D$39:$D$59,MATCH((($H23-MarketData!$B$4)/360),Bootstrap!$B$39:$B$59,1)+1)-INDEX(Bootstrap!$D$39:$D$59,MATCH((($H23-MarketData!$B$4)/360),Bootstrap!$B$39:$B$59,1)))*(((($H23-MarketData!$B$4)/360))-INDEX(Bootstrap!$B$39:$B$59,MATCH((($H23-MarketData!$B$4)/360),Bootstrap!$B$39:$B$59,1)))/(INDEX(Bootstrap!$B$39:$B$59,MATCH((($H23-MarketData!$B$4)/360),Bootstrap!$B$39:$B$59,1)+1)-INDEX(Bootstrap!$B$39:$B$59,MATCH((($H23-MarketData!$B$4)/360),Bootstrap!$B$39:$B$59,1)))) -> 0.94214151 | K23: =EXP(INDEX(Bootstrap!$D$39:$D$59,MATCH((($I23-MarketData!$B$4)/360),Bootstrap!$B$39:$B$59,1))+(INDEX(Bootstrap!$D$39:$D$59,MATCH((($I23-MarketData!$B$4)/360),Bootstrap!$B$39:$B$59,1)+1)-INDEX(Bootstrap!$D$39:$D$59,MATCH((($I23-MarketData!$B$4)/360),Bootstrap!$B$39:$B$59,1)))*(((($I23-MarketData!$B$4)/360))-INDEX(Bootstrap!$B$39:$B$59,MATCH((($I23-MarketData!$B$4)/360),Bootstrap!$B$39:$B$59,1)))/(INDEX(Bootstrap!$B$39:$B$59,MATCH((($I23-MarketData!$B$4)/360),Bootstrap!$B$39:$B$59,1)+1)-INDEX(Bootstrap!$B$39:$B$59,MATCH((($I23-MarketData!$B$4)/360),Bootstrap!$B$39:$B$59,1)))) -> 0.93894343 | L23: =(J23/K23-1)/G23 -> 0.039554097 | M23: =MarketData!$C$69 -> 0.039187225 | N23: =(L23-M23)*10000 -> 3.6687188
A24: =MarketData!$A$70 -> 46772 | B24: =(A24-MarketData!$B$4)/360 -> 1.6527778 | C24: =EXP(INDEX(Bootstrap!$D$39:$D$59,MATCH($B24,Bootstrap!$B$39:$B$59,1))+(INDEX(Bootstrap!$D$39:$D$59,MATCH($B24,Bootstrap!$B$39:$B$59,1)+1)-INDEX(Bootstrap!$D$39:$D$59,MATCH($B24,Bootstrap!$B$39:$B$59,1)))*(($B24)-INDEX(Bootstrap!$B$39:$B$59,MATCH($B24,Bootstrap!$B$39:$B$59,1)))/(INDEX(Bootstrap!$B$39:$B$59,MATCH($B24,Bootstrap!$B$39:$B$59,1)+1)-INDEX(Bootstrap!$B$39:$B$59,MATCH($B24,Bootstrap!$B$39:$B$59,1)))) -> 0.93822307 | D24: =MarketData!$B$70 -> 0.93833149 | E24: =(LN(D24)-LN(C24))/B24*10000 -> 0.69916184 | F24: =A25 -> 46805 | G24: =(F24-A24)/360 -> 0.091666667 | H24: =WORKDAY(A24,-5) -> 46765 | I24: =WORKDAY(F24,-5) -> 46798 | J24: =EXP(INDEX(Bootstrap!$D$39:$D$59,MATCH((($H24-MarketData!$B$4)/360),Bootstrap!$B$39:$B$59,1))+(INDEX(Bootstrap!$D$39:$D$59,MATCH((($H24-MarketData!$B$4)/360),Bootstrap!$B$39:$B$59,1)+1)-INDEX(Bootstrap!$D$39:$D$59,MATCH((($H24-MarketData!$B$4)/360),Bootstrap!$B$39:$B$59,1)))*(((($H24-MarketData!$B$4)/360))-INDEX(Bootstrap!$B$39:$B$59,MATCH((($H24-MarketData!$B$4)/360),Bootstrap!$B$39:$B$59,1)))/(INDEX(Bootstrap!$B$39:$B$59,MATCH((($H24-MarketData!$B$4)/360),Bootstrap!$B$39:$B$59,1)+1)-INDEX(Bootstrap!$B$39:$B$59,MATCH((($H24-MarketData!$B$4)/360),Bootstrap!$B$39:$B$59,1)))) -> 0.93894343 | K24: =EXP(INDEX(Bootstrap!$D$39:$D$59,MATCH((($I24-MarketData!$B$4)/360),Bootstrap!$B$39:$B$59,1))+(INDEX(Bootstrap!$D$39:$D$59,MATCH((($I24-MarketData!$B$4)/360),Bootstrap!$B$39:$B$59,1)+1)-INDEX(Bootstrap!$D$39:$D$59,MATCH((($I24-MarketData!$B$4)/360),Bootstrap!$B$39:$B$59,1)))*(((($I24-MarketData!$B$4)/360))-INDEX(Bootstrap!$B$39:$B$59,MATCH((($I24-MarketData!$B$4)/360),Bootstrap!$B$39:$B$59,1)))/(INDEX(Bootstrap!$B$39:$B$59,MATCH((($I24-MarketData!$B$4)/360),Bootstrap!$B$39:$B$59,1)+1)-INDEX(Bootstrap!$B$39:$B$59,MATCH((($I24-MarketData!$B$4)/360),Bootstrap!$B$39:$B$59,1)))) -> 0.93555227 | L24: =(J24/K24-1)/G24 -> 0.039542925 | M24: =MarketData!$C$70 -> 0.039005663 | N24: =(L24-M24)*10000 -> 5.3726181
A25: =MarketData!$A$71 -> 46805 | B25: =(A25-MarketData!$B$4)/360 -> 1.7444444 | C25: =EXP(INDEX(Bootstrap!$D$39:$D$59,MATCH($B25,Bootstrap!$B$39:$B$59,1))+(INDEX(Bootstrap!$D$39:$D$59,MATCH($B25,Bootstrap!$B$39:$B$59,1)+1)-INDEX(Bootstrap!$D$39:$D$59,MATCH($B25,Bootstrap!$B$39:$B$59,1)))*(($B25)-INDEX(Bootstrap!$B$39:$B$59,MATCH($B25,Bootstrap!$B$39:$B$59,1)))/(INDEX(Bootstrap!$B$39:$B$59,MATCH($B25,Bootstrap!$B$39:$B$59,1)+1)-INDEX(Bootstrap!$B$39:$B$59,MATCH($B25,Bootstrap!$B$39:$B$59,1)))) -> 0.93483451 | D25: =MarketData!$B$71 -> 0.93499187 | E25: =(LN(D25)-LN(C25))/B25*10000 -> 0.96485611 | F25: =A26 -> 46832 | G25: =(F25-A25)/360 -> 0.075 | H25: =WORKDAY(A25,-5) -> 46798 | I25: =WORKDAY(F25,-5) -> 46825 | J25: =EXP(INDEX(Bootstrap!$D$39:$D$59,MATCH((($H25-MarketData!$B$4)/360),Bootstrap!$B$39:$B$59,1))+(INDEX(Bootstrap!$D$39:$D$59,MATCH((($H25-MarketData!$B$4)/360),Bootstrap!$B$39:$B$59,1)+1)-INDEX(Bootstrap!$D$39:$D$59,MATCH((($H25-MarketData!$B$4)/360),Bootstrap!$B$39:$B$59,1)))*(((($H25-MarketData!$B$4)/360))-INDEX(Bootstrap!$B$39:$B$59,MATCH((($H25-MarketData!$B$4)/360),Bootstrap!$B$39:$B$59,1)))/(INDEX(Bootstrap!$B$39:$B$59,MATCH((($H25-MarketData!$B$4)/360),Bootstrap!$B$39:$B$59,1)+1)-INDEX(Bootstrap!$B$39:$B$59,MATCH((($H25-MarketData!$B$4)/360),Bootstrap!$B$39:$B$59,1)))) -> 0.93555227 | K25: =EXP(INDEX(Bootstrap!$D$39:$D$59,MATCH((($I25-MarketData!$B$4)/360),Bootstrap!$B$39:$B$59,1))+(INDEX(Bootstrap!$D$39:$D$59,MATCH((($I25-MarketData!$B$4)/360),Bootstrap!$B$39:$B$59,1)+1)-INDEX(Bootstrap!$D$39:$D$59,MATCH((($I25-MarketData!$B$4)/360),Bootstrap!$B$39:$B$59,1)))*(((($I25-MarketData!$B$4)/360))-INDEX(Bootstrap!$B$39:$B$59,MATCH((($I25-MarketData!$B$4)/360),Bootstrap!$B$39:$B$59,1)))/(INDEX(Bootstrap!$B$39:$B$59,MATCH((($I25-MarketData!$B$4)/360),Bootstrap!$B$39:$B$59,1)+1)-INDEX(Bootstrap!$B$39:$B$59,MATCH((($I25-MarketData!$B$4)/360),Bootstrap!$B$39:$B$59,1)))) -> 0.93278679 | L25: =(J25/K25-1)/G25 -> 0.039529913 | M25: =MarketData!$C$71 -> 0.038826478 | N25: =(L25-M25)*10000 -> 7.0343432
A26: =MarketData!$A$72 -> 46832 | B26: =(A26-MarketData!$B$4)/360 -> 1.8194444 | C26: =EXP(INDEX(Bootstrap!$D$39:$D$59,MATCH($B26,Bootstrap!$B$39:$B$59,1))+(INDEX(Bootstrap!$D$39:$D$59,MATCH($B26,Bootstrap!$B$39:$B$59,1)+1)-INDEX(Bootstrap!$D$39:$D$59,MATCH($B26,Bootstrap!$B$39:$B$59,1)))*(($B26)-INDEX(Bootstrap!$B$39:$B$59,MATCH($B26,Bootstrap!$B$39:$B$59,1)))/(INDEX(Bootstrap!$B$39:$B$59,MATCH($B26,Bootstrap!$B$39:$B$59,1)+1)-INDEX(Bootstrap!$B$39:$B$59,MATCH($B26,Bootstrap!$B$39:$B$59,1)))) -> 0.93207869 | D26: =MarketData!$B$72 -> 0.93228031 | E26: =(LN(D26)-LN(C26))/B26*10000 -> 1.1887702 | F26: =A27 -> 46863 | G26: =(F26-A26)/360 -> 0.086111111 | H26: =WORKDAY(A26,-5) -> 46825 | I26: =WORKDAY(F26,-5) -> 46856 | J26: =EXP(INDEX(Bootstrap!$D$39:$D$59,MATCH((($H26-MarketData!$B$4)/360),Bootstrap!$B$39:$B$59,1))+(INDEX(Bootstrap!$D$39:$D$59,MATCH((($H26-MarketData!$B$4)/360),Bootstrap!$B$39:$B$59,1)+1)-INDEX(Bootstrap!$D$39:$D$59,MATCH((($H26-MarketData!$B$4)/360),Bootstrap!$B$39:$B$59,1)))*(((($H26-MarketData!$B$4)/360))-INDEX(Bootstrap!$B$39:$B$59,MATCH((($H26-MarketData!$B$4)/360),Bootstrap!$B$39:$B$59,1)))/(INDEX(Bootstrap!$B$39:$B$59,MATCH((($H26-MarketData!$B$4)/360),Bootstrap!$B$39:$B$59,1)+1)-INDEX(Bootstrap!$B$39:$B$59,MATCH((($H26-MarketData!$B$4)/360),Bootstrap!$B$39:$B$59,1)))) -> 0.93278679 | K26: =EXP(INDEX(Bootstrap!$D$39:$D$59,MATCH((($I26-MarketData!$B$4)/360),Bootstrap!$B$39:$B$59,1))+(INDEX(Bootstrap!$D$39:$D$59,MATCH((($I26-MarketData!$B$4)/360),Bootstrap!$B$39:$B$59,1)+1)-INDEX(Bootstrap!$D$39:$D$59,MATCH((($I26-MarketData!$B$4)/360),Bootstrap!$B$39:$B$59,1)))*(((($I26-MarketData!$B$4)/360))-INDEX(Bootstrap!$B$39:$B$59,MATCH((($I26-MarketData!$B$4)/360),Bootstrap!$B$39:$B$59,1)))/(INDEX(Bootstrap!$B$39:$B$59,MATCH((($I26-MarketData!$B$4)/360),Bootstrap!$B$39:$B$59,1)+1)-INDEX(Bootstrap!$B$39:$B$59,MATCH((($I26-MarketData!$B$4)/360),Bootstrap!$B$39:$B$59,1)))) -> 0.92966529 | L26: =(J26/K26-1)/G26 -> 0.038992284 | M26: =MarketData!$C$72 -> 0.038666567 | N26: =(L26-M26)*10000 -> 3.2571683
A27: =MarketData!$A$73 -> 46863 | B27: =(A27-MarketData!$B$4)/360 -> 1.9055556 | C27: =EXP(INDEX(Bootstrap!$D$39:$D$59,MATCH($B27,Bootstrap!$B$39:$B$59,1))+(INDEX(Bootstrap!$D$39:$D$59,MATCH($B27,Bootstrap!$B$39:$B$59,1)+1)-INDEX(Bootstrap!$D$39:$D$59,MATCH($B27,Bootstrap!$B$39:$B$59,1)))*(($B27)-INDEX(Bootstrap!$B$39:$B$59,MATCH($B27,Bootstrap!$B$39:$B$59,1)))/(INDEX(Bootstrap!$B$39:$B$59,MATCH($B27,Bootstrap!$B$39:$B$59,1)+1)-INDEX(Bootstrap!$B$39:$B$59,MATCH($B27,Bootstrap!$B$39:$B$59,1)))) -> 0.92896255 | D27: =MarketData!$B$73 -> 0.92918873 | E27: =(LN(D27)-LN(C27))/B27*10000 -> 1.2775611 | F27: =A28 -> 46895 | G27: =(F27-A27)/360 -> 0.088888889 | H27: =WORKDAY(A27,-5) -> 46856 | I27: =WORKDAY(F27,-5) -> 46888 | J27: =EXP(INDEX(Bootstrap!$D$39:$D$59,MATCH((($H27-MarketData!$B$4)/360),Bootstrap!$B$39:$B$59,1))+(INDEX(Bootstrap!$D$39:$D$59,MATCH((($H27-MarketData!$B$4)/360),Bootstrap!$B$39:$B$59,1)+1)-INDEX(Bootstrap!$D$39:$D$59,MATCH((($H27-MarketData!$B$4)/360),Bootstrap!$B$39:$B$59,1)))*(((($H27-MarketData!$B$4)/360))-INDEX(Bootstrap!$B$39:$B$59,MATCH((($H27-MarketData!$B$4)/360),Bootstrap!$B$39:$B$59,1)))/(INDEX(Bootstrap!$B$39:$B$59,MATCH((($H27-MarketData!$B$4)/360),Bootstrap!$B$39:$B$59,1)+1)-INDEX(Bootstrap!$B$39:$B$59,MATCH((($H27-MarketData!$B$4)/360),Bootstrap!$B$39:$B$59,1)))) -> 0.92966529 | K27: =EXP(INDEX(Bootstrap!$D$39:$D$59,MATCH((($I27-MarketData!$B$4)/360),Bootstrap!$B$39:$B$59,1))+(INDEX(Bootstrap!$D$39:$D$59,MATCH((($I27-MarketData!$B$4)/360),Bootstrap!$B$39:$B$59,1)+1)-INDEX(Bootstrap!$D$39:$D$59,MATCH((($I27-MarketData!$B$4)/360),Bootstrap!$B$39:$B$59,1)))*(((($I27-MarketData!$B$4)/360))-INDEX(Bootstrap!$B$39:$B$59,MATCH((($I27-MarketData!$B$4)/360),Bootstrap!$B$39:$B$59,1)))/(INDEX(Bootstrap!$B$39:$B$59,MATCH((($I27-MarketData!$B$4)/360),Bootstrap!$B$39:$B$59,1)+1)-INDEX(Bootstrap!$B$39:$B$59,MATCH((($I27-MarketData!$B$4)/360),Bootstrap!$B$39:$B$59,1)))) -> 0.92645713 | L27: =(J27/K27-1)/G27 -> 0.038956714 | M27: =MarketData!$C$73 -> 0.038551188 | N27: =(L27-M27)*10000 -> 4.055255
A28: =MarketData!$A$74 -> 46895 | B28: =(A28-MarketData!$B$4)/360 -> 1.9944444 | C28: =EXP(INDEX(Bootstrap!$D$39:$D$59,MATCH($B28,Bootstrap!$B$39:$B$59,1))+(INDEX(Bootstrap!$D$39:$D$59,MATCH($B28,Bootstrap!$B$39:$B$59,1)+1)-INDEX(Bootstrap!$D$39:$D$59,MATCH($B28,Bootstrap!$B$39:$B$59,1)))*(($B28)-INDEX(Bootstrap!$B$39:$B$59,MATCH($B28,Bootstrap!$B$39:$B$59,1)))/(INDEX(Bootstrap!$B$39:$B$59,MATCH($B28,Bootstrap!$B$39:$B$59,1)+1)-INDEX(Bootstrap!$B$39:$B$59,MATCH($B28,Bootstrap!$B$39:$B$59,1)))) -> 0.92575683 | D28: =MarketData!$B$74 -> 0.92601763 | E28: =(LN(D28)-LN(C28))/B28*10000 -> 1.412315 | F28: =A29 -> 46924 | G28: =(F28-A28)/360 -> 0.080555556 | H28: =WORKDAY(A28,-5) -> 46888 | I28: =WORKDAY(F28,-5) -> 46917 | J28: =EXP(INDEX(Bootstrap!$D$39:$D$59,MATCH((($H28-MarketData!$B$4)/360),Bootstrap!$B$39:$B$59,1))+(INDEX(Bootstrap!$D$39:$D$59,MATCH((($H28-MarketData!$B$4)/360),Bootstrap!$B$39:$B$59,1)+1)-INDEX(Bootstrap!$D$39:$D$59,MATCH((($H28-MarketData!$B$4)/360),Bootstrap!$B$39:$B$59,1)))*(((($H28-MarketData!$B$4)/360))-INDEX(Bootstrap!$B$39:$B$59,MATCH((($H28-MarketData!$B$4)/360),Bootstrap!$B$39:$B$59,1)))/(INDEX(Bootstrap!$B$39:$B$59,MATCH((($H28-MarketData!$B$4)/360),Bootstrap!$B$39:$B$59,1)+1)-INDEX(Bootstrap!$B$39:$B$59,MATCH((($H28-MarketData!$B$4)/360),Bootstrap!$B$39:$B$59,1)))) -> 0.92645713 | K28: =EXP(INDEX(Bootstrap!$D$39:$D$59,MATCH((($I28-MarketData!$B$4)/360),Bootstrap!$B$39:$B$59,1))+(INDEX(Bootstrap!$D$39:$D$59,MATCH((($I28-MarketData!$B$4)/360),Bootstrap!$B$39:$B$59,1)+1)-INDEX(Bootstrap!$D$39:$D$59,MATCH((($I28-MarketData!$B$4)/360),Bootstrap!$B$39:$B$59,1)))*(((($I28-MarketData!$B$4)/360))-INDEX(Bootstrap!$B$39:$B$59,MATCH((($I28-MarketData!$B$4)/360),Bootstrap!$B$39:$B$59,1)))/(INDEX(Bootstrap!$B$39:$B$59,MATCH((($I28-MarketData!$B$4)/360),Bootstrap!$B$39:$B$59,1)+1)-INDEX(Bootstrap!$B$39:$B$59,MATCH((($I28-MarketData!$B$4)/360),Bootstrap!$B$39:$B$59,1)))) -> 0.92355931 | L28: =(J28/K28-1)/G28 -> 0.038950398 | M28: =MarketData!$C$74 -> 0.038434123 | N28: =(L28-M28)*10000 -> 5.1627563
